Workbook

Sheet Business Dashboard
A1: Business Control Dashboard
A3: Metric | B3: Value
A4: Initial stock items | B4: =SUM('Stock Master'!C2:C49)
A5: Current stock items on hand | B5: =SUM('Stock Master'!J2:J49)
A6: Stock sold to date | B6: =SUM('Stock Master'!I2:I49)
A7: Cash sales collected (RMB) | B7: =SUM('Daily Sales Log'!J2:J501)
A8: Credit cash collected (RMB) | B8: =SUM('Credit Sales Tracker'!H2:H501)
A9: Expenses paid (RMB) | B9: =SUM('Daily Expenses Log'!E2:E501)
A10: Supplier/creditor payments (RMB) | B10: =SUM('Creditors Tracker'!F2:F501)
A11: Cash in hand (RMB) | B11: ='Cash Position'!B10
A12: Credit sales outstanding (RMB) | B12: ='Cash Position'!B11
A13: Outstanding creditors (RMB) | B13: ='Cash Position'!B12
A14: Stock at selling value on hand (RMB) | B14: ='Cash Position'!B13
A17: How to use this workbook
A18: 1 | B18: During the day, write every sale and expense on the Daily Log Printable sheet or directly in the logs.
A19: 2 | B19: At the end of the day, enter sales into Daily Sales Log and expenses into Daily Expenses Log.
A20: 3 | B20: Credit sales should also be entered into Credit Sales Tracker so customer balances are visible.
A21: 4 | B21: Money owed to suppliers, transporters, agents, or other people goes into Creditors Tracker.
A22: 5 | B22: Cash Position and Stock Master update automatically from the logs.
A23: 6 | B23: The individual item pages from your earlier workbook remain for detailed manual checking if required.

Sheet Stock Master
A1: Item No. | B1: Product name | C1: Initial stock | D1: Unit cost RMB | E1: Selling price RMB | F1: Extra stock received / returns | G1: Cash qty sold | H1: Credit qty sold | I1: Total qty sold | J1: Closing stock | K1: Sales value RMB | L1: Closing stock value RMB
A2: 1 | B2: Children's Jackets (Girls) | C2: 10 | D2: 55 | E2: 110 | F2: 0 | G2: =SUMIF('Daily Sales Log'!$D:$D,A2,'Daily Sales Log'!$G:$G) | H2: =SUMIF('Daily Sales Log'!$D:$D,A2,'Daily Sales Log'!$H:$H) | I2: =G2+H2 | J2: =C2+F2-I2 | K2: =I2*E2 | L2: =J2*E2
A3: 2 | B3: Children's Jackets (Boys) | C3: 10 | D3: 45 | E3: 90 | F3: 0 | G3: =SUMIF('Daily Sales Log'!$D:$D,A3,'Daily Sales Log'!$G:$G) | H3: =SUMIF('Daily Sales Log'!$D:$D,A3,'Daily Sales Log'!$H:$H) | I3: =G3+H3 | J3: =C3+F3-I3 | K3: =I3*E3 | L3: =J3*E3
A4: 3 | B4: Toddler 2-Piece Clothing Suits | C4: 48 | D4: 32 | E4: 64 | F4: 0 | G4: =SUMIF('Daily Sales Log'!$D:$D,A4,'Daily Sales Log'!$G:$G) | H4: =SUMIF('Daily Sales Log'!$D:$D,A4,'Daily Sales Log'!$H:$H) | I4: =G4+H4 | J4: =C4+F4-I4 | K4: =I4*E4 | L4: =J4*E4
A5: 4 | B5: Children's Lace Dresses | C5: 10 | D5: 35 | E5: 70 | F5: 0 | G5: =SUMIF('Daily Sales Log'!$D:$D,A5,'Daily Sales Log'!$G:$G) | H5: =SUMIF('Daily Sales Log'!$D:$D,A5,'Daily Sales Log'!$H:$H) | I5: =G5+H5 | J5: =C5+F5-I5 | K5: =I5*E5 | L5: =J5*E5
A6: 5 | B6: Children's Denim Ankle-Length Pants | C6: 5 | D6: 23 | E6: 46 | F6: 0 | G6: =SUMIF('Daily Sales Log'!$D:$D,A6,'Daily Sales Log'!$G:$G) | H6: =SUMIF('Daily Sales Log'!$D:$D,A6,'Daily Sales Log'!$H:$H) | I6: =G6+H6 | J6: =C6+F6-I6 | K6: =I6*E6 | L6: =J6*E6
A7: 6 | B7: Children's Denim Casual Pants (Blue, Gold Rim) | C7: 5 | D7: 23 | E7: 46 | F7: 0 | G7: =SUMIF('Daily Sales Log'!$D:$D,A7,'Daily Sales Log'!$G:$G) | H7: =SUMIF('Daily Sales Log'!$D:$D,A7,'Daily Sales Log'!$H:$H) | I7: =G7+H7 | J7: =C7+F7-I7 | K7: =I7*E7 | L7: =J7*E7
A8: 7 | B8: Children's Casual Ankle-Length Pants (Navy Blue) | C8: 5 | D8: 23 | E8: 46 | F8: 0 | G8: =SUMIF('Daily Sales Log'!$D:$D,A8,'Daily Sales Log'!$G:$G) | H8: =SUMIF('Daily Sales Log'!$D:$D,A8,'Daily Sales Log'!$H:$H) | I8: =G8+H8 | J8: =C8+F8-I8 | K8: =I8*E8 | L8: =J8*E8
A9: 8 | B9: Children's Casual Cargo Trousers | C9: 5 | D9: 30 | E9: 60 | F9: 0 | G9: =SUMIF('Daily Sales Log'!$D:$D,A9,'Daily Sales Log'!$G:$G) | H9: =SUMIF('Daily Sales Log'!$D:$D,A9,'Daily Sales Log'!$H:$H) | I9: =G9+H9 | J9: =C9+F9-I9 | K9: =I9*E9 | L9: =J9*E9
A10: 9 | B10: Children's Long & Short Sleeve Matching Suits (Red) | C10: 10 | D10: 41 | E10: 82 | F10: 0 | G10: =SUMIF('Daily Sales Log'!$D:$D,A10,'Daily Sales Log'!$G:$G) | H10: =SUMIF('Daily Sales Log'!$D:$D,A10,'Daily Sales Log'!$H:$H) | I10: =G10+H10 | J10: =C10+F10-I10 | K10: =I10*E10 | L10: =J10*E10
A11: 10 | B11: Children's 2-Piece T-Shirt & Shorts Suits (Light Green) | C11: 5 | D11: 35 | E11: 70 | F11: 0 | G11: =SUMIF('Daily Sales Log'!$D:$D,A11,'Daily Sales Log'!$G:$G) | H11: =SUMIF('Daily Sales Log'!$D:$D,A11,'Daily Sales Log'!$H:$H) | I11: =G11+H11 | J11: =C11+F11-I11 | K11: =I11*E11 | L11: =J11*E11
A12: 11 | B12: Ladies' Woven Sweaters | C12: 50 | D12: 30 | E12: 60 | F12: 0 | G12: =SUMIF('Daily Sales Log'!$D:$D,A12,'Daily Sales Log'!$G:$G) | H12: =SUMIF('Daily Sales Log'!$D:$D,A12,'Daily Sales Log'!$H:$H) | I12: =G12+H12 | J12: =C12+F12-I12 | K12: =I12*E12 | L12: =J12*E12
A13: 12 | B13: Ladies' Denim Dresses | C13: 20 | D13: 42 | E13: 84 | F13: 0 | G13: =SUMIF('Daily Sales Log'!$D:$D,A13,'Daily Sales Log'!$G:$G) | H13: =SUMIF('Daily Sales Log'!$D:$D,A13,'Daily Sales Log'!$H:$H) | I13: =G13+H13 | J13: =C13+F13-I13 | K13: =I13*E13 | L13: =J13*E13
... A49: 48 | B49: Ladies' Fashion Cargo Dresses (Style D) | C49: 4 | D49: 108 | E49: 216 | F49: 0 | G49: =SUMIF('Daily Sales Log'!$D:$D,A49,'Daily Sales Log'!$G:$G) | H49: =SUMIF('Daily Sales Log'!$D:$D,A49,'Daily Sales Log'!$H:$H) | I49: =G49+H49 | J49: =C49+F49-I49 | K49: =I49*E49 | L49: =J49*E49

Sheet Daily Sales Log
A1: Date | B1: Receipt / Ref | C1: Customer name | D1: Item No. | E1: Product name | F1: Unit selling price RMB | G1: Qty sold cash | H1: Qty sold credit | I1: Total qty sold | J1: Cash sales RMB | K1: Credit sales RMB | L1: Payment method | M1: Notes
E2: =IFERROR(VLOOKUP(D2,'Stock Master'!$A$2:$L$49,2,FALSE),"") | F2: =IFERROR(VLOOKUP(D2,'Stock Master'!$A$2:$L$49,5,FALSE),"") | I2: =IFERROR(G2+H2,0) | J2: =IFERROR(F2*G2,0) | K2: =IFERROR(F2*H2,0)
E3: =IFERROR(VLOOKUP(D3,'Stock Master'!$A$2:$L$49,2,FALSE),"") | F3: =IFERROR(VLOOKUP(D3,'Stock Master'!$A$2:$L$49,5,FALSE),"") | I3: =IFERROR(G3+H3,0) | J3: =IFERROR(F3*G3,0) | K3: =IFERROR(F3*H3,0)
E4: =IFERROR(VLOOKUP(D4,'Stock Master'!$A$2:$L$49,2,FALSE),"") | F4: =IFERROR(VLOOKUP(D4,'Stock Master'!$A$2:$L$49,5,FALSE),"") | I4: =IFERROR(G4+H4,0) | J4: =IFERROR(F4*G4,0) | K4: =IFERROR(F4*H4,0)
E5: =IFERROR(VLOOKUP(D5,'Stock Master'!$A$2:$L$49,2,FALSE),"") | F5: =IFERROR(VLOOKUP(D5,'Stock Master'!$A$2:$L$49,5,FALSE),"") | I5: =IFERROR(G5+H5,0) | J5: =IFERROR(F5*G5,0) | K5: =IFERROR(F5*H5,0)
E6: =IFERROR(VLOOKUP(D6,'Stock Master'!$A$2:$L$49,2,FALSE),"") | F6: =IFERROR(VLOOKUP(D6,'Stock Master'!$A$2:$L$49,5,FALSE),"") | I6: =IFERROR(G6+H6,0) | J6: =IFERROR(F6*G6,0) | K6: =IFERROR(F6*H6,0)
E7: =IFERROR(VLOOKUP(D7,'Stock Master'!$A$2:$L$49,2,FALSE),"") | F7: =IFERROR(VLOOKUP(D7,'Stock Master'!$A$2:$L$49,5,FALSE),"") | I7: =IFERROR(G7+H7,0) | J7: =IFERROR(F7*G7,0) | K7: =IFERROR(F7*H7,0)
E8: =IFERROR(VLOOKUP(D8,'Stock Master'!$A$2:$L$49,2,FALSE),"") | F8: =IFERROR(VLOOKUP(D8,'Stock Master'!$A$2:$L$49,5,FALSE),"") | I8: =IFERROR(G8+H8,0) | J8: =IFERROR(F8*G8,0) | K8: =IFERROR(F8*H8,0)
E9: =IFERROR(VLOOKUP(D9,'Stock Master'!$A$2:$L$49,2,FALSE),"") | F9: =IFERROR(VLOOKUP(D9,'Stock Master'!$A$2:$L$49,5,FALSE),"") | I9: =IFERROR(G9+H9,0) | J9: =IFERROR(F9*G9,0) | K9: =IFERROR(F9*H9,0)
E10: =IFERROR(VLOOKUP(D10,'Stock Master'!$A$2:$L$49,2,FALSE),"") | F10: =IFERROR(VLOOKUP(D10,'Stock Master'!$A$2:$L$49,5,FALSE),"") | I10: =IFERROR(G10+H10,0) | J10: =IFERROR(F10*G10,0) | K10: =IFERROR(F10*H10,0)
E11: =IFERROR(VLOOKUP(D11,'Stock Master'!$A$2:$L$49,2,FALSE),"") | F11: =IFERROR(VLOOKUP(D11,'Stock Master'!$A$2:$L$49,5,FALSE),"") | I11: =IFERROR(G11+H11,0) | J11: =IFERROR(F11*G11,0) | K11: =IFERROR(F11*H11,0)
E12: =IFERROR(VLOOKUP(D12,'Stock Master'!$A$2:$L$49,2,FALSE),"") | F12: =IFERROR(VLOOKUP(D12,'Stock Master'!$A$2:$L$49,5,FALSE),"") | I12: =IFERROR(G12+H12,0) | J12: =IFERROR(F12*G12,0) | K12: =IFERROR(F12*H12,0)
E13: =IFERROR(VLOOKUP(D13,'Stock Master'!$A$2:$L$49,2,FALSE),"") | F13: =IFERROR(VLOOKUP(D13,'Stock Master'!$A$2:$L$49,5,FALSE),"") | I13: =IFERROR(G13+H13,0) | J13: =IFERROR(F13*G13,0) | K13: =IFERROR(F13*H13,0)
... E501: =IFERROR(VLOOKUP(D501,'Stock Master'!$A$2:$L$49,2,FALSE),"") | F501: =IFERROR(VLOOKUP(D501,'Stock Master'!$A$2:$L$49,5,FALSE),"") | I501: =IFERROR(G501+H501,0) | J501: =IFERROR(F501*G501,0) | K501: =IFERROR(F501*H501,0)

Sheet Daily Expenses Log
A1: Date | B1: Expense category | C1: Description | D1: Paid to | E1: Amount RMB | F1: Payment method | G1: Notes

Sheet Credit Sales Tracker
A1: Date sold | B1: Customer name | C1: Phone | D1: Item No. | E1: Product name | F1: Qty | G1: Amount owed RMB | H1: Amount paid RMB | I1: Payment date | J1: Balance RMB | K1: Due date | L1: Status | M1: Notes
E2: =IFERROR(VLOOKUP(D2,'Stock Master'!$A$2:$L$49,2,FALSE),"") | G2: =IFERROR(VLOOKUP(D2,'Stock Master'!$A$2:$L$49,5,FALSE)*F2,0) | J2: =IFERROR(G2-H2,0) | L2: =IF(A2="","",IF(J2<=0,"Paid",IF(AND(K2<TODAY(),K2<>""),"Overdue","Open")))
E3: =IFERROR(VLOOKUP(D3,'Stock Master'!$A$2:$L$49,2,FALSE),"") | G3: =IFERROR(VLOOKUP(D3,'Stock Master'!$A$2:$L$49,5,FALSE)*F3,0) | J3: =IFERROR(G3-H3,0) | L3: =IF(A3="","",IF(J3<=0,"Paid",IF(AND(K3<TODAY(),K3<>""),"Overdue","Open")))
E4: =IFERROR(VLOOKUP(D4,'Stock Master'!$A$2:$L$49,2,FALSE),"") | G4: =IFERROR(VLOOKUP(D4,'Stock Master'!$A$2:$L$49,5,FALSE)*F4,0) | J4: =IFERROR(G4-H4,0) | L4: =IF(A4="","",IF(J4<=0,"Paid",IF(AND(K4<TODAY(),K4<>""),"Overdue","Open")))
E5: =IFERROR(VLOOKUP(D5,'Stock Master'!$A$2:$L$49,2,FALSE),"") | G5: =IFERROR(VLOOKUP(D5,'Stock Master'!$A$2:$L$49,5,FALSE)*F5,0) | J5: =IFERROR(G5-H5,0) | L5: =IF(A5="","",IF(J5<=0,"Paid",IF(AND(K5<TODAY(),K5<>""),"Overdue","Open")))
E6: =IFERROR(VLOOKUP(D6,'Stock Master'!$A$2:$L$49,2,FALSE),"") | G6: =IFERROR(VLOOKUP(D6,'Stock Master'!$A$2:$L$49,5,FALSE)*F6,0) | J6: =IFERROR(G6-H6,0) | L6: =IF(A6="","",IF(J6<=0,"Paid",IF(AND(K6<TODAY(),K6<>""),"Overdue","Open")))
E7: =IFERROR(VLOOKUP(D7,'Stock Master'!$A$2:$L$49,2,FALSE),"") | G7: =IFERROR(VLOOKUP(D7,'Stock Master'!$A$2:$L$49,5,FALSE)*F7,0) | J7: =IFERROR(G7-H7,0) | L7: =IF(A7="","",IF(J7<=0,"Paid",IF(AND(K7<TODAY(),K7<>""),"Overdue","Open")))
E8: =IFERROR(VLOOKUP(D8,'Stock Master'!$A$2:$L$49,2,FALSE),"") | G8: =IFERROR(VLOOKUP(D8,'Stock Master'!$A$2:$L$49,5,FALSE)*F8,0) | J8: =IFERROR(G8-H8,0) | L8: =IF(A8="","",IF(J8<=0,"Paid",IF(AND(K8<TODAY(),K8<>""),"Overdue","Open")))
E9: =IFERROR(VLOOKUP(D9,'Stock Master'!$A$2:$L$49,2,FALSE),"") | G9: =IFERROR(VLOOKUP(D9,'Stock Master'!$A$2:$L$49,5,FALSE)*F9,0) | J9: =IFERROR(G9-H9,0) | L9: =IF(A9="","",IF(J9<=0,"Paid",IF(AND(K9<TODAY(),K9<>""),"Overdue","Open")))
E10: =IFERROR(VLOOKUP(D10,'Stock Master'!$A$2:$L$49,2,FALSE),"") | G10: =IFERROR(VLOOKUP(D10,'Stock Master'!$A$2:$L$49,5,FALSE)*F10,0) | J10: =IFERROR(G10-H10,0) | L10: =IF(A10="","",IF(J10<=0,"Paid",IF(AND(K10<TODAY(),K10<>""),"Overdue","Open")))
E11: =IFERROR(VLOOKUP(D11,'Stock Master'!$A$2:$L$49,2,FALSE),"") | G11: =IFERROR(VLOOKUP(D11,'Stock Master'!$A$2:$L$49,5,FALSE)*F11,0) | J11: =IFERROR(G11-H11,0) | L11: =IF(A11="","",IF(J11<=0,"Paid",IF(AND(K11<TODAY(),K11<>""),"Overdue","Open")))
E12: =IFERROR(VLOOKUP(D12,'Stock Master'!$A$2:$L$49,2,FALSE),"") | G12: =IFERROR(VLOOKUP(D12,'Stock Master'!$A$2:$L$49,5,FALSE)*F12,0) | J12: =IFERROR(G12-H12,0) | L12: =IF(A12="","",IF(J12<=0,"Paid",IF(AND(K12<TODAY(),K12<>""),"Overdue","Open")))
E13: =IFERROR(VLOOKUP(D13,'Stock Master'!$A$2:$L$49,2,FALSE),"") | G13: =IFERROR(VLOOKUP(D13,'Stock Master'!$A$2:$L$49,5,FALSE)*F13,0) | J13: =IFERROR(G13-H13,0) | L13: =IF(A13="","",IF(J13<=0,"Paid",IF(AND(K13<TODAY(),K13<>""),"Overdue","Open")))
... E501: =IFERROR(VLOOKUP(D501,'Stock Master'!$A$2:$L$49,2,FALSE),"") | G501: =IFERROR(VLOOKUP(D501,'Stock Master'!$A$2:$L$49,5,FALSE)*F501,0) | J501: =IFERROR(G501-H501,0) | L501: =IF(A501="","",IF(J501<=0,"Paid",IF(AND(K501<TODAY(),K501<>""),"Overdue","Open")))

Sheet Creditors Tracker
A1: Date owed | B1: Creditor / supplier | C1: Description | D1: Invoice / Ref | E1: Amount owed RMB | F1: Amount paid RMB | G1: Payment date | H1: Balance RMB | I1: Due date | J1: Status | K1: Notes
H2: =IFERROR(E2-F2,0) | J2: =IF(A2="","",IF(H2<=0,"Paid",IF(AND(I2<TODAY(),I2<>""),"Overdue","Open")))
H3: =IFERROR(E3-F3,0) | J3: =IF(A3="","",IF(H3<=0,"Paid",IF(AND(I3<TODAY(),I3<>""),"Overdue","Open")))
H4: =IFERROR(E4-F4,0) | J4: =IF(A4="","",IF(H4<=0,"Paid",IF(AND(I4<TODAY(),I4<>""),"Overdue","Open")))
H5: =IFERROR(E5-F5,0) | J5: =IF(A5="","",IF(H5<=0,"Paid",IF(AND(I5<TODAY(),I5<>""),"Overdue","Open")))
H6: =IFERROR(E6-F6,0) | J6: =IF(A6="","",IF(H6<=0,"Paid",IF(AND(I6<TODAY(),I6<>""),"Overdue","Open")))
H7: =IFERROR(E7-F7,0) | J7: =IF(A7="","",IF(H7<=0,"Paid",IF(AND(I7<TODAY(),I7<>""),"Overdue","Open")))
H8: =IFERROR(E8-F8,0) | J8: =IF(A8="","",IF(H8<=0,"Paid",IF(AND(I8<TODAY(),I8<>""),"Overdue","Open")))
H9: =IFERROR(E9-F9,0) | J9: =IF(A9="","",IF(H9<=0,"Paid",IF(AND(I9<TODAY(),I9<>""),"Overdue","Open")))
H10: =IFERROR(E10-F10,0) | J10: =IF(A10="","",IF(H10<=0,"Paid",IF(AND(I10<TODAY(),I10<>""),"Overdue","Open")))
H11: =IFERROR(E11-F11,0) | J11: =IF(A11="","",IF(H11<=0,"Paid",IF(AND(I11<TODAY(),I11<>""),"Overdue","Open")))
H12: =IFERROR(E12-F12,0) | J12: =IF(A12="","",IF(H12<=0,"Paid",IF(AND(I12<TODAY(),I12<>""),"Overdue","Open")))
H13: =IFERROR(E13-F13,0) | J13: =IF(A13="","",IF(H13<=0,"Paid",IF(AND(I13<TODAY(),I13<>""),"Overdue","Open")))
... H501: =IFERROR(E501-F501,0) | J501: =IF(A501="","",IF(H501<=0,"Paid",IF(AND(I501<TODAY(),I501<>""),"Overdue","Open")))

Sheet Cash Position
A1: Cash Position Tracker
A3: Opening cash float / cash on hand at day one (RMB) | B3: 0
A4: Cash sales collected (RMB) | B4: =SUM('Daily Sales Log'!J2:J501)
A5: Credit customer payments collected (RMB) | B5: =SUM('Credit Sales Tracker'!H2:H501)
A6: Total cash inflow (RMB) | B6: =SUM(B4:B5)
A7: Expenses paid (RMB) | B7: =SUM('Daily Expenses Log'!E2:E501)
A8: Payments to creditors/suppliers (RMB) | B8: =SUM('Creditors Tracker'!F2:F501)
A9: Total cash outflow (RMB) | B9: =SUM(B7:B8)
A10: Cash in hand now (RMB) | B10: =B3+B6-B9
A11: Credit sales outstanding (RMB) | B11: =SUM('Credit Sales Tracker'!J2:J501)
A12: Outstanding creditors/suppliers (RMB) | B12: =SUM('Creditors Tracker'!H2:H501)
A13: Stock at selling value on hand (RMB) | B13: =SUM('Stock Master'!L2:L49)
A16: Cash Count Check
A17: Physical cash counted at end of day (RMB)
A18: Expected cash in workbook (RMB) | B18: =B10
A19: Difference | B19: =B17-B18
A20: Notes / reason for difference

Sheet Daily Closing Log
A1: Date | B1: Opening cash | C1: Cash sales | D1: Credit cash collected | E1: Expenses paid | F1: Creditor payments | G1: Closing cash | H1: Total stock on hand | I1: Credit sales outstanding | J1: Creditors outstanding | K1: Notes
B2: ='Cash Position'!$B$3 | C2: =IF(A2="","",SUMIFS('Daily Sales Log'!$J:$J,'Daily Sales Log'!$A:$A,A2)) | D2: =IF(A2="","",SUMIFS('Credit Sales Tracker'!$H:$H,'Credit Sales Tracker'!$I:$I,A2)) | E2: =IF(A2="","",SUMIFS('Daily Expenses Log'!$E:$E,'Daily Expenses Log'!$A:$A,A2)) | F2: =IF(A2="","",SUMIFS('Creditors Tracker'!$F:$F,'Creditors Tracker'!$G:$G,A2)) | G2: =IF(A2="","",B2+C2+D2-E2-F2) | H2: =IF(A2="","",SUM('Stock Master'!$J$2:$J$49)) | I2: =IF(A2="","",SUM('Credit Sales Tracker'!$J$2:$J$501)) | J2: =IF(A2="","",SUM('Creditors Tracker'!$H$2:$H$501))
B3: =IF(A3="","",G2) | C3: =IF(A3="","",SUMIFS('Daily Sales Log'!$J:$J,'Daily Sales Log'!$A:$A,A3)) | D3: =IF(A3="","",SUMIFS('Credit Sales Tracker'!$H:$H,'Credit Sales Tracker'!$I:$I,A3)) | E3: =IF(A3="","",SUMIFS('Daily Expenses Log'!$E:$E,'Daily Expenses Log'!$A:$A,A3)) | F3: =IF(A3="","",SUMIFS('Creditors Tracker'!$F:$F,'Creditors Tracker'!$G:$G,A3)) | G3: =IF(A3="","",B3+C3+D3-E3-F3) | H3: =IF(A3="","",SUM('Stock Master'!$J$2:$J$49)) | I3: =IF(A3="","",SUM('Credit Sales Tracker'!$J$2:$J$501)) | J3: =IF(A3="","",SUM('Creditors Tracker'!$H$2:$H$501))
B4: =IF(A4="","",G3) | C4: =IF(A4="","",SUMIFS('Daily Sales Log'!$J:$J,'Daily Sales Log'!$A:$A,A4)) | D4: =IF(A4="","",SUMIFS('Credit Sales Tracker'!$H:$H,'Credit Sales Tracker'!$I:$I,A4)) | E4: =IF(A4="","",SUMIFS('Daily Expenses Log'!$E:$E,'Daily Expenses Log'!$A:$A,A4)) | F4: =IF(A4="","",SUMIFS('Creditors Tracker'!$F:$F,'Creditors Tracker'!$G:$G,A4)) | G4: =IF(A4="","",B4+C4+D4-E4-F4) | H4: =IF(A4="","",SUM('Stock Master'!$J$2:$J$49)) | I4: =IF(A4="","",SUM('Credit Sales Tracker'!$J$2:$J$501)) | J4: =IF(A4="","",SUM('Creditors Tracker'!$H$2:$H$501))
B5: =IF(A5="","",G4) | C5: =IF(A5="","",SUMIFS('Daily Sales Log'!$J:$J,'Daily Sales Log'!$A:$A,A5)) | D5: =IF(A5="","",SUMIFS('Credit Sales Tracker'!$H:$H,'Credit Sales Tracker'!$I:$I,A5)) | E5: =IF(A5="","",SUMIFS('Daily Expenses Log'!$E:$E,'Daily Expenses Log'!$A:$A,A5)) | F5: =IF(A5="","",SUMIFS('Creditors Tracker'!$F:$F,'Creditors Tracker'!$G:$G,A5)) | G5: =IF(A5="","",B5+C5+D5-E5-F5) | H5: =IF(A5="","",SUM('Stock Master'!$J$2:$J$49)) | I5: =IF(A5="","",SUM('Credit Sales Tracker'!$J$2:$J$501)) | J5: =IF(A5="","",SUM('Creditors Tracker'!$H$2:$H$501))
B6: =IF(A6="","",G5) | C6: =IF(A6="","",SUMIFS('Daily Sales Log'!$J:$J,'Daily Sales Log'!$A:$A,A6)) | D6: =IF(A6="","",SUMIFS('Credit Sales Tracker'!$H:$H,'Credit Sales Tracker'!$I:$I,A6)) | E6: =IF(A6="","",SUMIFS('Daily Expenses Log'!$E:$E,'Daily Expenses Log'!$A:$A,A6)) | F6: =IF(A6="","",SUMIFS('Creditors Tracker'!$F:$F,'Creditors Tracker'!$G:$G,A6)) | G6: =IF(A6="","",B6+C6+D6-E6-F6) | H6: =IF(A6="","",SUM('Stock Master'!$J$2:$J$49)) | I6: =IF(A6="","",SUM('Credit Sales Tracker'!$J$2:$J$501)) | J6: =IF(A6="","",SUM('Creditors Tracker'!$H$2:$H$501))
B7: =IF(A7="","",G6) | C7: =IF(A7="","",SUMIFS('Daily Sales Log'!$J:$J,'Daily Sales Log'!$A:$A,A7)) | D7: =IF(A7="","",SUMIFS('Credit Sales Tracker'!$H:$H,'Credit Sales Tracker'!$I:$I,A7)) | E7: =IF(A7="","",SUMIFS('Daily Expenses Log'!$E:$E,'Daily Expenses Log'!$A:$A,A7)) | F7: =IF(A7="","",SUMIFS('Creditors Tracker'!$F:$F,'Creditors Tracker'!$G:$G,A7)) | G7: =IF(A7="","",B7+C7+D7-E7-F7) | H7: =IF(A7="","",SUM('Stock Master'!$J$2:$J$49)) | I7: =IF(A7="","",SUM('Credit Sales Tracker'!$J$2:$J$501)) | J7: =IF(A7="","",SUM('Creditors Tracker'!$H$2:$H$501))
B8: =IF(A8="","",G7) | C8: =IF(A8="","",SUMIFS('Daily Sales Log'!$J:$J,'Daily Sales Log'!$A:$A,A8)) | D8: =IF(A8="","",SUMIFS('Credit Sales Tracker'!$H:$H,'Credit Sales Tracker'!$I:$I,A8)) | E8: =IF(A8="","",SUMIFS('Daily Expenses Log'!$E:$E,'Daily Expenses Log'!$A:$A,A8)) | F8: =IF(A8="","",SUMIFS('Creditors Tracker'!$F:$F,'Creditors Tracker'!$G:$G,A8)) | G8: =IF(A8="","",B8+C8+D8-E8-F8) | H8: =IF(A8="","",SUM('Stock Master'!$J$2:$J$49)) | I8: =IF(A8="","",SUM('Credit Sales Tracker'!$J$2:$J$501)) | J8: =IF(A8="","",SUM('Creditors Tracker'!$H$2:$H$501))
B9: =IF(A9="","",G8) | C9: =IF(A9="","",SUMIFS('Daily Sales Log'!$J:$J,'Daily Sales Log'!$A:$A,A9)) | D9: =IF(A9="","",SUMIFS('Credit Sales Tracker'!$H:$H,'Credit Sales Tracker'!$I:$I,A9)) | E9: =IF(A9="","",SUMIFS('Daily Expenses Log'!$E:$E,'Daily Expenses Log'!$A:$A,A9)) | F9: =IF(A9="","",SUMIFS('Creditors Tracker'!$F:$F,'Creditors Tracker'!$G:$G,A9)) | G9: =IF(A9="","",B9+C9+D9-E9-F9) | H9: =IF(A9="","",SUM('Stock Master'!$J$2:$J$49)) | I9: =IF(A9="","",SUM('Credit Sales Tracker'!$J$2:$J$501)) | J9: =IF(A9="","",SUM('Creditors Tracker'!$H$2:$H$501))
B10: =IF(A10="","",G9) | C10: =IF(A10="","",SUMIFS('Daily Sales Log'!$J:$J,'Daily Sales Log'!$A:$A,A10)) | D10: =IF(A10="","",SUMIFS('Credit Sales Tracker'!$H:$H,'Credit Sales Tracker'!$I:$I,A10)) | E10: =IF(A10="","",SUMIFS('Daily Expenses Log'!$E:$E,'Daily Expenses Log'!$A:$A,A10)) | F10: =IF(A10="","",SUMIFS('Creditors Tracker'!$F:$F,'Creditors Tracker'!$G:$G,A10)) | G10: =IF(A10="","",B10+C10+D10-E10-F10) | H10: =IF(A10="","",SUM('Stock Master'!$J$2:$J$49)) | I10: =IF(A10="","",SUM('Credit Sales Tracker'!$J$2:$J$501)) | J10: =IF(A10="","",SUM('Creditors Tracker'!$H$2:$H$501))
B11: =IF(A11="","",G10) | C11: =IF(A11="","",SUMIFS('Daily Sales Log'!$J:$J,'Daily Sales Log'!$A:$A,A11)) | D11: =IF(A11="","",SUMIFS('Credit Sales Tracker'!$H:$H,'Credit Sales Tracker'!$I:$I,A11)) | E11: =IF(A11="","",SUMIFS('Daily Expenses Log'!$E:$E,'Daily Expenses Log'!$A:$A,A11)) | F11: =IF(A11="","",SUMIFS('Creditors Tracker'!$F:$F,'Creditors Tracker'!$G:$G,A11)) | G11: =IF(A11="","",B11+C11+D11-E11-F11) | H11: =IF(A11="","",SUM('Stock Master'!$J$2:$J$49)) | I11: =IF(A11="","",SUM('Credit Sales Tracker'!$J$2:$J$501)) | J11: =IF(A11="","",SUM('Creditors Tracker'!$H$2:$H$501))
B12: =IF(A12="","",G11) | C12: =IF(A12="","",SUMIFS('Daily Sales Log'!$J:$J,'Daily Sales Log'!$A:$A,A12)) | D12: =IF(A12="","",SUMIFS('Credit Sales Tracker'!$H:$H,'Credit Sales Tracker'!$I:$I,A12)) | E12: =IF(A12="","",SUMIFS('Daily Expenses Log'!$E:$E,'Daily Expenses Log'!$A:$A,A12)) | F12: =IF(A12="","",SUMIFS('Creditors Tracker'!$F:$F,'Creditors Tracker'!$G:$G,A12)) | G12: =IF(A12="","",B12+C12+D12-E12-F12) | H12: =IF(A12="","",SUM('Stock Master'!$J$2:$J$49)) | I12: =IF(A12="","",SUM('Credit Sales Tracker'!$J$2:$J$501)) | J12: =IF(A12="","",SUM('Creditors Tracker'!$H$2:$H$501))
B13: =IF(A13="","",G12) | C13: =IF(A13="","",SUMIFS('Daily Sales Log'!$J:$J,'Daily Sales Log'!$A:$A,A13)) | D13: =IF(A13="","",SUMIFS('Credit Sales Tracker'!$H:$H,'Credit Sales Tracker'!$I:$I,A13)) | E13: =IF(A13="","",SUMIFS('Daily Expenses Log'!$E:$E,'Daily Expenses Log'!$A:$A,A13)) | F13: =IF(A13="","",SUMIFS('Creditors Tracker'!$F:$F,'Creditors Tracker'!$G:$G,A13)) | G13: =IF(A13="","",B13+C13+D13-E13-F13) | H13: =IF(A13="","",SUM('Stock Master'!$J$2:$J$49)) | I13: =IF(A13="","",SUM('Credit Sales Tracker'!$J$2:$J$501)) | J13: =IF(A13="","",SUM('Creditors Tracker'!$H$2:$H$501))
B14: =IF(A14="","",G13) | C14: =IF(A14="","",SUMIFS('Daily Sales Log'!$J:$J,'Daily Sales Log'!$A:$A,A14)) | D14: =IF(A14="","",SUMIFS('Credit Sales Tracker'!$H:$H,'Credit Sales Tracker'!$I:$I,A14)) | E14: =IF(A14="","",SUMIFS('Daily Expenses Log'!$E:$E,'Daily Expenses Log'!$A:$A,A14)) | F14: =IF(A14="","",SUMIFS('Creditors Tracker'!$F:$F,'Creditors Tracker'!$G:$G,A14)) | G14: =IF(A14="","",B14+C14+D14-E14-F14) | H14: =IF(A14="","",SUM('Stock Master'!$J$2:$J$49)) | I14: =IF(A14="","",SUM('Credit Sales Tracker'!$J$2:$J$501)) | J14: =IF(A14="","",SUM('Creditors Tracker'!$H$2:$H$501))
... B366: =IF(A366="","",G365) | C366: =IF(A366="","",SUMIFS('Daily Sales Log'!$J:$J,'Daily Sales Log'!$A:$A,A366)) | D366: =IF(A366="","",SUMIFS('Credit Sales Tracker'!$H:$H,'Credit Sales Tracker'!$I:$I,A366)) | E366: =IF(A366="","",SUMIFS('Daily Expenses Log'!$E:$E,'Daily Expenses Log'!$A:$A,A366)) | F366: =IF(A366="","",SUMIFS('Creditors Tracker'!$F:$F,'Creditors Tracker'!$G:$G,A366)) | G366: =IF(A366="","",B366+C366+D366-E366-F366) | H366: =IF(A366="","",SUM('Stock Master'!$J$2:$J$49)) | I366: =IF(A366="","",SUM('Credit Sales Tracker'!$J$2:$J$501)) | J366: =IF(A366="","",SUM('Creditors Tracker'!$H$2:$H$501))

Sheet Daily Log Printable
A1: Daily Business Log - Manual Page
A2: Date: | C2: Prepared by: | E2: Opening cash: | G2: Page no.:
A3: Total cash counted at close: | C3: Expected cash: | E3: Difference: | G3: Checked by:
A6: Sales During the Day
A7: Item No. | B7: Product name | C7: Qty cash | D7: Qty credit | E7: Unit price | F7: Cash received | G7: Credit customer | H7: Notes
A30: Expenses During the Day
A31: Expense category | B31: Description | C31: Paid to | D31: Amount | E31: Payment method | F31: Receipt/ref | G31: Approved by | H31: Notes
A44: Credit Follow-Up / Debtors and Creditors Notes
A45: Type | B45: Person / business | C45: Phone | D45: Description | E45: Amount | F45: Due date | G45: Action taken | H45: Notes

Sheet Summary
A1: NO. | B1: Product name | C1: Initial stock | D1: Unit cost (RMB) | E1: Selling price/item (RMB) | F1: Unit cost (USD) | G1: Selling price/item (USD) | H1: Total cost (RMB) | I1: Expected revenue (RMB) | J1: Expected gross profit (RMB)
A2: 1 | B2: Children's Jackets (Girls) | C2: 10 | D2: 55 | E2: 110 | F2: 8.13 | G2: 16.26 | H2: 550 | I2: 1100 | J2: 550
A3: 2 | B3: Children's Jackets (Boys) | C3: 10 | D3: 45 | E3: 90 | F3: 6.65 | G3: 13.3 | H3: 450 | I3: 900 | J3: 450
A4: 3 | B4: Toddler 2-Piece Clothing Suits | C4: 48 | D4: 32 | E4: 64 | F4: 4.73 | G4: 9.46 | H4: 1536 | I4: 3072 | J4: 1536
A5: 4 | B5: Children's Lace Dresses | C5: 10 | D5: 35 | E5: 70 | F5: 5.17 | G5: 10.35 | H5: 350 | I5: 700 | J5: 350
A6: 5 | B6: Children's Denim Ankle-Length Pants | C6: 5 | D6: 23 | E6: 46 | F6: 3.4 | G6: 6.8 | H6: 115 | I6: 230 | J6: 115
A7: 6 | B7: Children's Denim Casual Pants (Blue, Gold Rim) | C7: 5 | D7: 23 | E7: 46 | F7: 3.4 | G7: 6.8 | H7: 115 | I7: 230 | J7: 115
A8: 7 | B8: Children's Casual Ankle-Length Pants (Navy Blue) | C8: 5 | D8: 23 | E8: 46 | F8: 3.4 | G8: 6.8 | H8: 115 | I8: 230 | J8: 115
A9: 8 | B9: Children's Casual Cargo Trousers | C9: 5 | D9: 30 | E9: 60 | F9: 4.43 | G9: 8.87 | H9: 150 | I9: 300 | J9: 150
A10: 9 | B10: Children's Long & Short Sleeve Matching Suits (Red) | C10: 10 | D10: 41 | E10: 82 | F10: 6.06 | G10: 12.12 | H10: 410 | I10: 820 | J10: 410
A11: 10 | B11: Children's 2-Piece T-Shirt & Shorts Suits (Light Green) | C11: 5 | D11: 35 | E11: 70 | F11: 5.17 | G11: 10.35 | H11: 175 | I11: 350 | J11: 175
A12: 11 | B12: Ladies' Woven Sweaters | C12: 50 | D12: 30 | E12: 60 | F12: 4.43 | G12: 8.87 | H12: 1500 | I12: 3000 | J12: 1500
A13: 12 | B13: Ladies' Denim Dresses | C13: 20 | D13: 42 | E13: 84 | F13: 6.21 | G13: 12.42 | H13: 840 | I13: 1680 | J13: 840
... A49: 48 | B49: Ladies' Fashion Cargo Dresses (Style D) | C49: 4 | D49: 108 | E49: 216 | F49: 15.96 | G49: 31.92 | H49: 432 | I49: 864 | J49: 432
B50: TOTAL | C50: 1044 | H50: 24414.33 | I50: 48828.66 | J50: 24414.33

Sheet 01 Childrens Jackets Girls
A1: Stock Item Tracking Sheet
A2: Item No. | B2: 1
A3: Product name | B3: Children's Jackets (Girls)
A4: Initial stock quantity | B4: 10
A5: Unit cost (RMB) | B5: 55
A6: Selling price/item (RMB) | B6: 110
A7: Unit cost (USD) | B7: 8.13
A8: Selling price/item (USD) | B8: 16.26
A10: Date | B10: Opening balance | C10: Stock received | D10: Quantity sold | E10: Returns | F10: Closing balance | G10: Sales value (RMB) | H10: Sales value (USD) | I10: Notes
B11: =$B$4 | C11: 0 | D11: 0 | E11: 0 | F11: =B11+C11+E11-D11 | G11: =D11*$B$6 | H11: =D11*$B$8
B12: =F11 | C12: 0 | D12: 0 | E12: 0 | F12: =B12+C12+E12-D12 | G12: =D12*$B$6 | H12: =D12*$B$8
B13: =F12 | C13: 0 | D13: 0 | E13: 0 | F13: =B13+C13+E13-D13 | G13: =D13*$B$6 | H13: =D13*$B$8
B14: =F13 | C14: 0 | D14: 0 | E14: 0 | F14: =B14+C14+E14-D14 | G14: =D14*$B$6 | H14: =D14*$B$8
B15: =F14 | C15: 0 | D15: 0 | E15: 0 | F15: =B15+C15+E15-D15 | G15: =D15*$B$6 | H15: =D15*$B$8
B16: =F15 | C16: 0 | D16: 0 | E16: 0 | F16: =B16+C16+E16-D16 | G16: =D16*$B$6 | H16: =D16*$B$8
B17: =F16 | C17: 0 | D17: 0 | E17: 0 | F17: =B17+C17+E17-D17 | G17: =D17*$B$6 | H17: =D17*$B$8
B18: =F17 | C18: 0 | D18: 0 | E18: 0 | F18: =B18+C18+E18-D18 | G18: =D18*$B$6 | H18: =D18*$B$8
B19: =F18 | C19: 0 | D19: 0 | E19: 0 | F19: =B19+C19+E19-D19 | G19: =D19*$B$6 | H19: =D19*$B$8
B20: =F19 | C20: 0 | D20: 0 | E20: 0 | F20: =B20+C20+E20-D20 | G20: =D20*$B$6 | H20: =D20*$B$8
B21: =F20 | C21: 0 | D21: 0 | E21: 0 | F21: =B21+C21+E21-D21 | G21: =D21*$B$6 | H21: =D21*$B$8
B22: =F21 | C22: 0 | D22: 0 | E22: 0 | F22: =B22+C22+E22-D22 | G22: =D22*$B$6 | H22: =D22*$B$8
B23: =F22 | C23: 0 | D23: 0 | E23: 0 | F23: =B23+C23+E23-D23 | G23: =D23*$B$6 | H23: =D23*$B$8
... B110: =F109 | C110: 0 | D110: 0 | E110: 0 | F110: =B110+C110+E110-D110 | G110: =D110*$B$6 | H110: =D110*$B$8

Sheet 02 Childrens Jackets Boys
A1: Stock Item Tracking Sheet
A2: Item No. | B2: 2
A3: Product name | B3: Children's Jackets (Boys)
A4: Initial stock quantity | B4: 10
A5: Unit cost (RMB) | B5: 45
A6: Selling price/item (RMB) | B6: 90
A7: Unit cost (USD) | B7: 6.65
A8: Selling price/item (USD) | B8: 13.3
A10: Date | B10: Opening balance | C10: Stock received | D10: Quantity sold | E10: Returns | F10: Closing balance | G10: Sales value (RMB) | H10: Sales value (USD) | I10: Notes
B11: =$B$4 | C11: 0 | D11: 0 | E11: 0 | F11: =B11+C11+E11-D11 | G11: =D11*$B$6 | H11: =D11*$B$8
B12: =F11 | C12: 0 | D12: 0 | E12: 0 | F12: =B12+C12+E12-D12 | G12: =D12*$B$6 | H12: =D12*$B$8
B13: =F12 | C13: 0 | D13: 0 | E13: 0 | F13: =B13+C13+E13-D13 | G13: =D13*$B$6 | H13: =D13*$B$8
B14: =F13 | C14: 0 | D14: 0 | E14: 0 | F14: =B14+C14+E14-D14 | G14: =D14*$B$6 | H14: =D14*$B$8
B15: =F14 | C15: 0 | D15: 0 | E15: 0 | F15: =B15+C15+E15-D15 | G15: =D15*$B$6 | H15: =D15*$B$8
B16: =F15 | C16: 0 | D16: 0 | E16: 0 | F16: =B16+C16+E16-D16 | G16: =D16*$B$6 | H16: =D16*$B$8
B17: =F16 | C17: 0 | D17: 0 | E17: 0 | F17: =B17+C17+E17-D17 | G17: =D17*$B$6 | H17: =D17*$B$8
B18: =F17 | C18: 0 | D18: 0 | E18: 0 | F18: =B18+C18+E18-D18 | G18: =D18*$B$6 | H18: =D18*$B$8
B19: =F18 | C19: 0 | D19: 0 | E19: 0 | F19: =B19+C19+E19-D19 | G19: =D19*$B$6 | H19: =D19*$B$8
B20: =F19 | C20: 0 | D20: 0 | E20: 0 | F20: =B20+C20+E20-D20 | G20: =D20*$B$6 | H20: =D20*$B$8
B21: =F20 | C21: 0 | D21: 0 | E21: 0 | F21: =B21+C21+E21-D21 | G21: =D21*$B$6 | H21: =D21*$B$8
B22: =F21 | C22: 0 | D22: 0 | E22: 0 | F22: =B22+C22+E22-D22 | G22: =D22*$B$6 | H22: =D22*$B$8
B23: =F22 | C23: 0 | D23: 0 | E23: 0 | F23: =B23+C23+E23-D23 | G23: =D23*$B$6 | H23: =D23*$B$8
... B110: =F109 | C110: 0 | D110: 0 | E110: 0 | F110: =B110+C110+E110-D110 | G110: =D110*$B$6 | H110: =D110*$B$8

Sheet 03 Toddler 2Piece Clothing Suit
A1: Stock Item Tracking Sheet
A2: Item No. | B2: 3
A3: Product name | B3: Toddler 2-Piece Clothing Suits
A4: Initial stock quantity | B4: 48
A5: Unit cost (RMB) | B5: 32
A6: Selling price/item (RMB) | B6: 64
A7: Unit cost (USD) | B7: 4.73
A8: Selling price/item (USD) | B8: 9.46
A10: Date | B10: Opening balance | C10: Stock received | D10: Quantity sold | E10: Returns | F10: Closing balance | G10: Sales value (RMB) | H10: Sales value (USD) | I10: Notes
B11: =$B$4 | C11: 0 | D11: 0 | E11: 0 | F11: =B11+C11+E11-D11 | G11: =D11*$B$6 | H11: =D11*$B$8
B12: =F11 | C12: 0 | D12: 0 | E12: 0 | F12: =B12+C12+E12-D12 | G12: =D12*$B$6 | H12: =D12*$B$8
B13: =F12 | C13: 0 | D13: 0 | E13: 0 | F13: =B13+C13+E13-D13 | G13: =D13*$B$6 | H13: =D13*$B$8
B14: =F13 | C14: 0 | D14: 0 | E14: 0 | F14: =B14+C14+E14-D14 | G14: =D14*$B$6 | H14: =D14*$B$8
B15: =F14 | C15: 0 | D15: 0 | E15: 0 | F15: =B15+C15+E15-D15 | G15: =D15*$B$6 | H15: =D15*$B$8
B16: =F15 | C16: 0 | D16: 0 | E16: 0 | F16: =B16+C16+E16-D16 | G16: =D16*$B$6 | H16: =D16*$B$8
B17: =F16 | C17: 0 | D17: 0 | E17: 0 | F17: =B17+C17+E17-D17 | G17: =D17*$B$6 | H17: =D17*$B$8
B18: =F17 | C18: 0 | D18: 0 | E18: 0 | F18: =B18+C18+E18-D18 | G18: =D18*$B$6 | H18: =D18*$B$8
B19: =F18 | C19: 0 | D19: 0 | E19: 0 | F19: =B19+C19+E19-D19 | G19: =D19*$B$6 | H19: =D19*$B$8
B20: =F19 | C20: 0 | D20: 0 | E20: 0 | F20: =B20+C20+E20-D20 | G20: =D20*$B$6 | H20: =D20*$B$8
B21: =F20 | C21: 0 | D21: 0 | E21: 0 | F21: =B21+C21+E21-D21 | G21: =D21*$B$6 | H21: =D21*$B$8
B22: =F21 | C22: 0 | D22: 0 | E22: 0 | F22: =B22+C22+E22-D22 | G22: =D22*$B$6 | H22: =D22*$B$8
B23: =F22 | C23: 0 | D23: 0 | E23: 0 | F23: =B23+C23+E23-D23 | G23: =D23*$B$6 | H23: =D23*$B$8
... B110: =F109 | C110: 0 | D110: 0 | E110: 0 | F110: =B110+C110+E110-D110 | G110: =D110*$B$6 | H110: =D110*$B$8

Sheet 04 Childrens Lace Dresses
A1: Stock Item Tracking Sheet
A2: Item No. | B2: 4
A3: Product name | B3: Children's Lace Dresses
A4: Initial stock quantity | B4: 10
A5: Unit cost (RMB) | B5: 35
A6: Selling price/item (RMB) | B6: 70
A7: Unit cost (USD) | B7: 5.17
A8: Selling price/item (USD) | B8: 10.35
A10: Date | B10: Opening balance | C10: Stock received | D10: Quantity sold | E10: Returns | F10: Closing balance | G10: Sales value (RMB) | H10: Sales value (USD) | I10: Notes
B11: =$B$4 | C11: 0 | D11: 0 | E11: 0 | F11: =B11+C11+E11-D11 | G11: =D11*$B$6 | H11: =D11*$B$8
B12: =F11 | C12: 0 | D12: 0 | E12: 0 | F12: =B12+C12+E12-D12 | G12: =D12*$B$6 | H12: =D12*$B$8
B13: =F12 | C13: 0 | D13: 0 | E13: 0 | F13: =B13+C13+E13-D13 | G13: =D13*$B$6 | H13: =D13*$B$8
B14: =F13 | C14: 0 | D14: 0 | E14: 0 | F14: =B14+C14+E14-D14 | G14: =D14*$B$6 | H14: =D14*$B$8
B15: =F14 | C15: 0 | D15: 0 | E15: 0 | F15: =B15+C15+E15-D15 | G15: =D15*$B$6 | H15: =D15*$B$8
B16: =F15 | C16: 0 | D16: 0 | E16: 0 | F16: =B16+C16+E16-D16 | G16: =D16*$B$6 | H16: =D16*$B$8
B17: =F16 | C17: 0 | D17: 0 | E17: 0 | F17: =B17+C17+E17-D17 | G17: =D17*$B$6 | H17: =D17*$B$8
B18: =F17 | C18: 0 | D18: 0 | E18: 0 | F18: =B18+C18+E18-D18 | G18: =D18*$B$6 | H18: =D18*$B$8
B19: =F18 | C19: 0 | D19: 0 | E19: 0 | F19: =B19+C19+E19-D19 | G19: =D19*$B$6 | H19: =D19*$B$8
B20: =F19 | C20: 0 | D20: 0 | E20: 0 | F20: =B20+C20+E20-D20 | G20: =D20*$B$6 | H20: =D20*$B$8
B21: =F20 | C21: 0 | D21: 0 | E21: 0 | F21: =B21+C21+E21-D21 | G21: =D21*$B$6 | H21: =D21*$B$8
B22: =F21 | C22: 0 | D22: 0 | E22: 0 | F22: =B22+C22+E22-D22 | G22: =D22*$B$6 | H22: =D22*$B$8
B23: =F22 | C23: 0 | D23: 0 | E23: 0 | F23: =B23+C23+E23-D23 | G23: =D23*$B$6 | H23: =D23*$B$8
... B110: =F109 | C110: 0 | D110: 0 | E110: 0 | F110: =B110+C110+E110-D110 | G110: =D110*$B$6 | H110: =D110*$B$8

Sheet 05 Childrens Denim AnkleLength
A1: Stock Item Tracking Sheet
A2: Item No. | B2: 5
A3: Product name | B3: Children's Denim Ankle-Length Pants
A4: Initial stock quantity | B4: 5
A5: Unit cost (RMB) | B5: 23
A6: Selling price/item (RMB) | B6: 46
A7: Unit cost (USD) | B7: 3.4
A8: Selling price/item (USD) | B8: 6.8
A10: Date | B10: Opening balance | C10: Stock received | D10: Quantity sold | E10: Returns | F10: Closing balance | G10: Sales value (RMB) | H10: Sales value (USD) | I10: Notes
B11: =$B$4 | C11: 0 | D11: 0 | E11: 0 | F11: =B11+C11+E11-D11 | G11: =D11*$B$6 | H11: =D11*$B$8
B12: =F11 | C12: 0 | D12: 0 | E12: 0 | F12: =B12+C12+E12-D12 | G12: =D12*$B$6 | H12: =D12*$B$8
B13: =F12 | C13: 0 | D13: 0 | E13: 0 | F13: =B13+C13+E13-D13 | G13: =D13*$B$6 | H13: =D13*$B$8
B14: =F13 | C14: 0 | D14: 0 | E14: 0 | F14: =B14+C14+E14-D14 | G14: =D14*$B$6 | H14: =D14*$B$8
B15: =F14 | C15: 0 | D15: 0 | E15: 0 | F15: =B15+C15+E15-D15 | G15: =D15*$B$6 | H15: =D15*$B$8
B16: =F15 | C16: 0 | D16: 0 | E16: 0 | F16: =B16+C16+E16-D16 | G16: =D16*$B$6 | H16: =D16*$B$8
B17: =F16 | C17: 0 | D17: 0 | E17: 0 | F17: =B17+C17+E17-D17 | G17: =D17*$B$6 | H17: =D17*$B$8
B18: =F17 | C18: 0 | D18: 0 | E18: 0 | F18: =B18+C18+E18-D18 | G18: =D18*$B$6 | H18: =D18*$B$8
B19: =F18 | C19: 0 | D19: 0 | E19: 0 | F19: =B19+C19+E19-D19 | G19: =D19*$B$6 | H19: =D19*$B$8
B20: =F19 | C20: 0 | D20: 0 | E20: 0 | F20: =B20+C20+E20-D20 | G20: =D20*$B$6 | H20: =D20*$B$8
B21: =F20 | C21: 0 | D21: 0 | E21: 0 | F21: =B21+C21+E21-D21 | G21: =D21*$B$6 | H21: =D21*$B$8
B22: =F21 | C22: 0 | D22: 0 | E22: 0 | F22: =B22+C22+E22-D22 | G22: =D22*$B$6 | H22: =D22*$B$8
B23: =F22 | C23: 0 | D23: 0 | E23: 0 | F23: =B23+C23+E23-D23 | G23: =D23*$B$6 | H23: =D23*$B$8
... B110: =F109 | C110: 0 | D110: 0 | E110: 0 | F110: =B110+C110+E110-D110 | G110: =D110*$B$6 | H110: =D110*$B$8

Sheet 06 Childrens Denim Casual Pants
A1: Stock Item Tracking Sheet
A2: Item No. | B2: 6
A3: Product name | B3: Children's Denim Casual Pants (Blue, Gold Rim)
A4: Initial stock quantity | B4: 5
A5: Unit cost (RMB) | B5: 23
A6: Selling price/item (RMB) | B6: 46
A7: Unit cost (USD) | B7: 3.4
A8: Selling price/item (USD) | B8: 6.8
A10: Date | B10: Opening balance | C10: Stock received | D10: Quantity sold | E10: Returns | F10: Closing balance | G10: Sales value (RMB) | H10: Sales value (USD) | I10: Notes
B11: =$B$4 | C11: 0 | D11: 0 | E11: 0 | F11: =B11+C11+E11-D11 | G11: =D11*$B$6 | H11: =D11*$B$8
B12: =F11 | C12: 0 | D12: 0 | E12: 0 | F12: =B12+C12+E12-D12 | G12: =D12*$B$6 | H12: =D12*$B$8
B13: =F12 | C13: 0 | D13: 0 | E13: 0 | F13: =B13+C13+E13-D13 | G13: =D13*$B$6 | H13: =D13*$B$8
B14: =F13 | C14: 0 | D14: 0 | E14: 0 | F14: =B14+C14+E14-D14 | G14: =D14*$B$6 | H14: =D14*$B$8
B15: =F14 | C15: 0 | D15: 0 | E15: 0 | F15: =B15+C15+E15-D15 | G15: =D15*$B$6 | H15: =D15*$B$8
B16: =F15 | C16: 0 | D16: 0 | E16: 0 | F16: =B16+C16+E16-D16 | G16: =D16*$B$6 | H16: =D16*$B$8
B17: =F16 | C17: 0 | D17: 0 | E17: 0 | F17: =B17+C17+E17-D17 | G17: =D17*$B$6 | H17: =D17*$B$8
B18: =F17 | C18: 0 | D18: 0 | E18: 0 | F18: =B18+C18+E18-D18 | G18: =D18*$B$6 | H18: =D18*$B$8
B19: =F18 | C19: 0 | D19: 0 | E19: 0 | F19: =B19+C19+E19-D19 | G19: =D19*$B$6 | H19: =D19*$B$8
B20: =F19 | C20: 0 | D20: 0 | E20: 0 | F20: =B20+C20+E20-D20 | G20: =D20*$B$6 | H20: =D20*$B$8
B21: =F20 | C21: 0 | D21: 0 | E21: 0 | F21: =B21+C21+E21-D21 | G21: =D21*$B$6 | H21: =D21*$B$8
B22: =F21 | C22: 0 | D22: 0 | E22: 0 | F22: =B22+C22+E22-D22 | G22: =D22*$B$6 | H22: =D22*$B$8
B23: =F22 | C23: 0 | D23: 0 | E23: 0 | F23: =B23+C23+E23-D23 | G23: =D23*$B$6 | H23: =D23*$B$8
... B110: =F109 | C110: 0 | D110: 0 | E110: 0 | F110: =B110+C110+E110-D110 | G110: =D110*$B$6 | H110: =D110*$B$8

Sheet 07 Childrens Casual AnkleLength
A1: Stock Item Tracking Sheet
A2: Item No. | B2: 7
A3: Product name | B3: Children's Casual Ankle-Length Pants (Navy Blue)
A4: Initial stock quantity | B4: 5
A5: Unit cost (RMB) | B5: 23
A6: Selling price/item (RMB) | B6: 46
A7: Unit cost (USD) | B7: 3.4
A8: Selling price/item (USD) | B8: 6.8
A10: Date | B10: Opening balance | C10: Stock received | D10: Quantity sold | E10: Returns | F10: Closing balance | G10: Sales value (RMB) | H10: Sales value (USD) | I10: Notes
B11: =$B$4 | C11: 0 | D11: 0 | E11: 0 | F11: =B11+C11+E11-D11 | G11: =D11*$B$6 | H11: =D11*$B$8
B12: =F11 | C12: 0 | D12: 0 | E12: 0 | F12: =B12+C12+E12-D12 | G12: =D12*$B$6 | H12: =D12*$B$8
B13: =F12 | C13: 0 | D13: 0 | E13: 0 | F13: =B13+C13+E13-D13 | G13: =D13*$B$6 | H13: =D13*$B$8
B14: =F13 | C14: 0 | D14: 0 | E14: 0 | F14: =B14+C14+E14-D14 | G14: =D14*$B$6 | H14: =D14*$B$8
B15: =F14 | C15: 0 | D15: 0 | E15: 0 | F15: =B15+C15+E15-D15 | G15: =D15*$B$6 | H15: =D15*$B$8
B16: =F15 | C16: 0 | D16: 0 | E16: 0 | F16: =B16+C16+E16-D16 | G16: =D16*$B$6 | H16: =D16*$B$8
B17: =F16 | C17: 0 | D17: 0 | E17: 0 | F17: =B17+C17+E17-D17 | G17: =D17*$B$6 | H17: =D17*$B$8
B18: =F17 | C18: 0 | D18: 0 | E18: 0 | F18: =B18+C18+E18-D18 | G18: =D18*$B$6 | H18: =D18*$B$8
B19: =F18 | C19: 0 | D19: 0 | E19: 0 | F19: =B19+C19+E19-D19 | G19: =D19*$B$6 | H19: =D19*$B$8
B20: =F19 | C20: 0 | D20: 0 | E20: 0 | F20: =B20+C20+E20-D20 | G20: =D20*$B$6 | H20: =D20*$B$8
B21: =F20 | C21: 0 | D21: 0 | E21: 0 | F21: =B21+C21+E21-D21 | G21: =D21*$B$6 | H21: =D21*$B$8
B22: =F21 | C22: 0 | D22: 0 | E22: 0 | F22: =B22+C22+E22-D22 | G22: =D22*$B$6 | H22: =D22*$B$8
B23: =F22 | C23: 0 | D23: 0 | E23: 0 | F23: =B23+C23+E23-D23 | G23: =D23*$B$6 | H23: =D23*$B$8
... B110: =F109 | C110: 0 | D110: 0 | E110: 0 | F110: =B110+C110+E110-D110 | G110: =D110*$B$6 | H110: =D110*$B$8

Sheet 08 Childrens Casual Cargo Trous
A1: Stock Item Tracking Sheet
A2: Item No. | B2: 8
A3: Product name | B3: Children's Casual Cargo Trousers
A4: Initial stock quantity | B4: 5
A5: Unit cost (RMB) | B5: 30
A6: Selling price/item (RMB) | B6: 60
A7: Unit cost (USD) | B7: 4.43
A8: Selling price/item (USD) | B8: 8.87
A10: Date | B10: Opening balance | C10: Stock received | D10: Quantity sold | E10: Returns | F10: Closing balance | G10: Sales value (RMB) | H10: Sales value (USD) | I10: Notes
B11: =$B$4 | C11: 0 | D11: 0 | E11: 0 | F11: =B11+C11+E11-D11 | G11: =D11*$B$6 | H11: =D11*$B$8
B12: =F11 | C12: 0 | D12: 0 | E12: 0 | F12: =B12+C12+E12-D12 | G12: =D12*$B$6 | H12: =D12*$B$8
B13: =F12 | C13: 0 | D13: 0 | E13: 0 | F13: =B13+C13+E13-D13 | G13: =D13*$B$6 | H13: =D13*$B$8
B14: =F13 | C14: 0 | D14: 0 | E14: 0 | F14: =B14+C14+E14-D14 | G14: =D14*$B$6 | H14: =D14*$B$8
B15: =F14 | C15: 0 | D15: 0 | E15: 0 | F15: =B15+C15+E15-D15 | G15: =D15*$B$6 | H15: =D15*$B$8
B16: =F15 | C16: 0 | D16: 0 | E16: 0 | F16: =B16+C16+E16-D16 | G16: =D16*$B$6 | H16: =D16*$B$8
B17: =F16 | C17: 0 | D17: 0 | E17: 0 | F17: =B17+C17+E17-D17 | G17: =D17*$B$6 | H17: =D17*$B$8
B18: =F17 | C18: 0 | D18: 0 | E18: 0 | F18: =B18+C18+E18-D18 | G18: =D18*$B$6 | H18: =D18*$B$8
B19: =F18 | C19: 0 | D19: 0 | E19: 0 | F19: =B19+C19+E19-D19 | G19: =D19*$B$6 | H19: =D19*$B$8
B20: =F19 | C20: 0 | D20: 0 | E20: 0 | F20: =B20+C20+E20-D20 | G20: =D20*$B$6 | H20: =D20*$B$8
B21: =F20 | C21: 0 | D21: 0 | E21: 0 | F21: =B21+C21+E21-D21 | G21: =D21*$B$6 | H21: =D21*$B$8
B22: =F21 | C22: 0 | D22: 0 | E22: 0 | F22: =B22+C22+E22-D22 | G22: =D22*$B$6 | H22: =D22*$B$8
B23: =F22 | C23: 0 | D23: 0 | E23: 0 | F23: =B23+C23+E23-D23 | G23: =D23*$B$6 | H23: =D23*$B$8
... B110: =F109 | C110: 0 | D110: 0 | E110: 0 | F110: =B110+C110+E110-D110 | G110: =D110*$B$6 | H110: =D110*$B$8

Sheet 09 Childrens Long Short Sleeve
A1: Stock Item Tracking Sheet
A2: Item No. | B2: 9
A3: Product name | B3: Children's Long & Short Sleeve Matching Suits (Red)
A4: Initial stock quantity | B4: 10
A5: Unit cost (RMB) | B5: 41
A6: Selling price/item (RMB) | B6: 82
A7: Unit cost (USD) | B7: 6.06
A8: Selling price/item (USD) | B8: 12.12
A10: Date | B10: Opening balance | C10: Stock received | D10: Quantity sold | E10: Returns | F10: Closing balance | G10: Sales value (RMB) | H10: Sales value (USD) | I10: Notes
B11: =$B$4 | C11: 0 | D11: 0 | E11: 0 | F11: =B11+C11+E11-D11 | G11: =D11*$B$6 | H11: =D11*$B$8
B12: =F11 | C12: 0 | D12: 0 | E12: 0 | F12: =B12+C12+E12-D12 | G12: =D12*$B$6 | H12: =D12*$B$8
B13: =F12 | C13: 0 | D13: 0 | E13: 0 | F13: =B13+C13+E13-D13 | G13: =D13*$B$6 | H13: =D13*$B$8
B14: =F13 | C14: 0 | D14: 0 | E14: 0 | F14: =B14+C14+E14-D14 | G14: =D14*$B$6 | H14: =D14*$B$8
B15: =F14 | C15: 0 | D15: 0 | E15: 0 | F15: =B15+C15+E15-D15 | G15: =D15*$B$6 | H15: =D15*$B$8
B16: =F15 | C16: 0 | D16: 0 | E16: 0 | F16: =B16+C16+E16-D16 | G16: =D16*$B$6 | H16: =D16*$B$8
B17: =F16 | C17: 0 | D17: 0 | E17: 0 | F17: =B17+C17+E17-D17 | G17: =D17*$B$6 | H17: =D17*$B$8
B18: =F17 | C18: 0 | D18: 0 | E18: 0 | F18: =B18+C18+E18-D18 | G18: =D18*$B$6 | H18: =D18*$B$8
B19: =F18 | C19: 0 | D19: 0 | E19: 0 | F19: =B19+C19+E19-D19 | G19: =D19*$B$6 | H19: =D19*$B$8
B20: =F19 | C20: 0 | D20: 0 | E20: 0 | F20: =B20+C20+E20-D20 | G20: =D20*$B$6 | H20: =D20*$B$8
B21: =F20 | C21: 0 | D21: 0 | E21: 0 | F21: =B21+C21+E21-D21 | G21: =D21*$B$6 | H21: =D21*$B$8
B22: =F21 | C22: 0 | D22: 0 | E22: 0 | F22: =B22+C22+E22-D22 | G22: =D22*$B$6 | H22: =D22*$B$8
B23: =F22 | C23: 0 | D23: 0 | E23: 0 | F23: =B23+C23+E23-D23 | G23: =D23*$B$6 | H23: =D23*$B$8
... B110: =F109 | C110: 0 | D110: 0 | E110: 0 | F110: =B110+C110+E110-D110 | G110: =D110*$B$6 | H110: =D110*$B$8

Sheet 10 Childrens 2Piece TShirt Shor
A1: Stock Item Tracking Sheet
A2: Item No. | B2: 10
A3: Product name | B3: Children's 2-Piece T-Shirt & Shorts Suits (Light Green)
A4: Initial stock quantity | B4: 5
A5: Unit cost (RMB) | B5: 35
A6: Selling price/item (RMB) | B6: 70
A7: Unit cost (USD) | B7: 5.17
A8: Selling price/item (USD) | B8: 10.35
A10: Date | B10: Opening balance | C10: Stock received | D10: Quantity sold | E10: Returns | F10: Closing balance | G10: Sales value (RMB) | H10: Sales value (USD) | I10: Notes
B11: =$B$4 | C11: 0 | D11: 0 | E11: 0 | F11: =B11+C11+E11-D11 | G11: =D11*$B$6 | H11: =D11*$B$8
B12: =F11 | C12: 0 | D12: 0 | E12: 0 | F12: =B12+C12+E12-D12 | G12: =D12*$B$6 | H12: =D12*$B$8
B13: =F12 | C13: 0 | D13: 0 | E13: 0 | F13: =B13+C13+E13-D13 | G13: =D13*$B$6 | H13: =D13*$B$8
B14: =F13 | C14: 0 | D14: 0 | E14: 0 | F14: =B14+C14+E14-D14 | G14: =D14*$B$6 | H14: =D14*$B$8
B15: =F14 | C15: 0 | D15: 0 | E15: 0 | F15: =B15+C15+E15-D15 | G15: =D15*$B$6 | H15: =D15*$B$8
B16: =F15 | C16: 0 | D16: 0 | E16: 0 | F16: =B16+C16+E16-D16 | G16: =D16*$B$6 | H16: =D16*$B$8
B17: =F16 | C17: 0 | D17: 0 | E17: 0 | F17: =B17+C17+E17-D17 | G17: =D17*$B$6 | H17: =D17*$B$8
B18: =F17 | C18: 0 | D18: 0 | E18: 0 | F18: =B18+C18+E18-D18 | G18: =D18*$B$6 | H18: =D18*$B$8
B19: =F18 | C19: 0 | D19: 0 | E19: 0 | F19: =B19+C19+E19-D19 | G19: =D19*$B$6 | H19: =D19*$B$8
B20: =F19 | C20: 0 | D20: 0 | E20: 0 | F20: =B20+C20+E20-D20 | G20: =D20*$B$6 | H20: =D20*$B$8
B21: =F20 | C21: 0 | D21: 0 | E21: 0 | F21: =B21+C21+E21-D21 | G21: =D21*$B$6 | H21: =D21*$B$8
B22: =F21 | C22: 0 | D22: 0 | E22: 0 | F22: =B22+C22+E22-D22 | G22: =D22*$B$6 | H22: =D22*$B$8
B23: =F22 | C23: 0 | D23: 0 | E23: 0 | F23: =B23+C23+E23-D23 | G23: =D23*$B$6 | H23: =D23*$B$8
... B110: =F109 | C110: 0 | D110: 0 | E110: 0 | F110: =B110+C110+E110-D110 | G110: =D110*$B$6 | H110: =D110*$B$8

Sheet 11 Ladies Woven Sweaters
A1: Stock Item Tracking Sheet
A2: Item No. | B2: 11
A3: Product name | B3: Ladies' Woven Sweaters
A4: Initial stock quantity | B4: 50
A5: Unit cost (RMB) | B5: 30
A6: Selling price/item (RMB) | B6: 60
A7: Unit cost (USD) | B7: 4.43
A8: Selling price/item (USD) | B8: 8.87
A10: Date | B10: Opening balance | C10: Stock received | D10: Quantity sold | E10: Returns | F10: Closing balance | G10: Sales value (RMB) | H10: Sales value (USD) | I10: Notes
B11: =$B$4 | C11: 0 | D11: 0 | E11: 0 | F11: =B11+C11+E11-D11 | G11: =D11*$B$6 | H11: =D11*$B$8
B12: =F11 | C12: 0 | D12: 0 | E12: 0 | F12: =B12+C12+E12-D12 | G12: =D12*$B$6 | H12: =D12*$B$8
B13: =F12 | C13: 0 | D13: 0 | E13: 0 | F13: =B13+C13+E13-D13 | G13: =D13*$B$6 | H13: =D13*$B$8
B14: =F13 | C14: 0 | D14: 0 | E14: 0 | F14: =B14+C14+E14-D14 | G14: =D14*$B$6 | H14: =D14*$B$8
B15: =F14 | C15: 0 | D15: 0 | E15: 0 | F15: =B15+C15+E15-D15 | G15: =D15*$B$6 | H15: =D15*$B$8
B16: =F15 | C16: 0 | D16: 0 | E16: 0 | F16: =B16+C16+E16-D16 | G16: =D16*$B$6 | H16: =D16*$B$8
B17: =F16 | C17: 0 | D17: 0 | E17: 0 | F17: =B17+C17+E17-D17 | G17: =D17*$B$6 | H17: =D17*$B$8
B18: =F17 | C18: 0 | D18: 0 | E18: 0 | F18: =B18+C18+E18-D18 | G18: =D18*$B$6 | H18: =D18*$B$8
B19: =F18 | C19: 0 | D19: 0 | E19: 0 | F19: =B19+C19+E19-D19 | G19: =D19*$B$6 | H19: =D19*$B$8
B20: =F19 | C20: 0 | D20: 0 | E20: 0 | F20: =B20+C20+E20-D20 | G20: =D20*$B$6 | H20: =D20*$B$8
B21: =F20 | C21: 0 | D21: 0 | E21: 0 | F21: =B21+C21+E21-D21 | G21: =D21*$B$6 | H21: =D21*$B$8
B22: =F21 | C22: 0 | D22: 0 | E22: 0 | F22: =B22+C22+E22-D22 | G22: =D22*$B$6 | H22: =D22*$B$8
B23: =F22 | C23: 0 | D23: 0 | E23: 0 | F23: =B23+C23+E23-D23 | G23: =D23*$B$6 | H23: =D23*$B$8
... B110: =F109 | C110: 0 | D110: 0 | E110: 0 | F110: =B110+C110+E110-D110 | G110: =D110*$B$6 | H110: =D110*$B$8

Sheet 12 Ladies Denim Dresses
A1: Stock Item Tracking Sheet
A2: Item No. | B2: 12
A3: Product name | B3: Ladies' Denim Dresses
A4: Initial stock quantity | B4: 20
A5: Unit cost (RMB) | B5: 42
A6: Selling price/item (RMB) | B6: 84
A7: Unit cost (USD) | B7: 6.21
A8: Selling price/item (USD) | B8: 12.42
A10: Date | B10: Opening balance | C10: Stock received | D10: Quantity sold | E10: Returns | F10: Closing balance | G10: Sales value (RMB) | H10: Sales value (USD) | I10: Notes
B11: =$B$4 | C11: 0 | D11: 0 | E11: 0 | F11: =B11+C11+E11-D11 | G11: =D11*$B$6 | H11: =D11*$B$8
B12: =F11 | C12: 0 | D12: 0 | E12: 0 | F12: =B12+C12+E12-D12 | G12: =D12*$B$6 | H12: =D12*$B$8
B13: =F12 | C13: 0 | D13: 0 | E13: 0 | F13: =B13+C13+E13-D13 | G13: =D13*$B$6 | H13: =D13*$B$8
B14: =F13 | C14: 0 | D14: 0 | E14: 0 | F14: =B14+C14+E14-D14 | G14: =D14*$B$6 | H14: =D14*$B$8
B15: =F14 | C15: 0 | D15: 0 | E15: 0 | F15: =B15+C15+E15-D15 | G15: =D15*$B$6 | H15: =D15*$B$8
B16: =F15 | C16: 0 | D16: 0 | E16: 0 | F16: =B16+C16+E16-D16 | G16: =D16*$B$6 | H16: =D16*$B$8
B17: =F16 | C17: 0 | D17: 0 | E17: 0 | F17: =B17+C17+E17-D17 | G17: =D17*$B$6 | H17: =D17*$B$8
B18: =F17 | C18: 0 | D18: 0 | E18: 0 | F18: =B18+C18+E18-D18 | G18: =D18*$B$6 | H18: =D18*$B$8
B19: =F18 | C19: 0 | D19: 0 | E19: 0 | F19: =B19+C19+E19-D19 | G19: =D19*$B$6 | H19: =D19*$B$8
B20: =F19 | C20: 0 | D20: 0 | E20: 0 | F20: =B20+C20+E20-D20 | G20: =D20*$B$6 | H20: =D20*$B$8
B21: =F20 | C21: 0 | D21: 0 | E21: 0 | F21: =B21+C21+E21-D21 | G21: =D21*$B$6 | H21: =D21*$B$8
B22: =F21 | C22: 0 | D22: 0 | E22: 0 | F22: =B22+C22+E22-D22 | G22: =D22*$B$6 | H22: =D22*$B$8
B23: =F22 | C23: 0 | D23: 0 | E23: 0 | F23: =B23+C23+E23-D23 | G23: =D23*$B$6 | H23: =D23*$B$8
... B110: =F109 | C110: 0 | D110: 0 | E110: 0 | F110: =B110+C110+E110-D110 | G110: =D110*$B$6 | H110: =D110*$B$8

Sheet 13 Mens Woven Sweaters Style 19
A1: Stock Item Tracking Sheet
A2: Item No. | B2: 13
A3: Product name | B3: Men's Woven Sweaters (Style 19309)
A4: Initial stock quantity | B4: 12
A5: Unit cost (RMB) | B5: 35
A6: Selling price/item (RMB) | B6: 70
A7: Unit cost (USD) | B7: 5.17
A8: Selling price/item (USD) | B8: 10.35
A10: Date | B10: Opening balance | C10: Stock received | D10: Quantity sold | E10: Returns | F10: Closing balance | G10: Sales value (RMB) | H10: Sales value (USD) | I10: Notes
B11: =$B$4 | C11: 0 | D11: 0 | E11: 0 | F11: =B11+C11+E11-D11 | G11: =D11*$B$6 | H11: =D11*$B$8
B12: =F11 | C12: 0 | D12: 0 | E12: 0 | F12: =B12+C12+E12-D12 | G12: =D12*$B$6 | H12: =D12*$B$8
B13: =F12 | C13: 0 | D13: 0 | E13: 0 | F13: =B13+C13+E13-D13 | G13: =D13*$B$6 | H13: =D13*$B$8
B14: =F13 | C14: 0 | D14: 0 | E14: 0 | F14: =B14+C14+E14-D14 | G14: =D14*$B$6 | H14: =D14*$B$8
B15: =F14 | C15: 0 | D15: 0 | E15: 0 | F15: =B15+C15+E15-D15 | G15: =D15*$B$6 | H15: =D15*$B$8
B16: =F15 | C16: 0 | D16: 0 | E16: 0 | F16: =B16+C16+E16-D16 | G16: =D16*$B$6 | H16: =D16*$B$8
B17: =F16 | C17: 0 | D17: 0 | E17: 0 | F17: =B17+C17+E17-D17 | G17: =D17*$B$6 | H17: =D17*$B$8
B18: =F17 | C18: 0 | D18: 0 | E18: 0 | F18: =B18+C18+E18-D18 | G18: =D18*$B$6 | H18: =D18*$B$8
B19: =F18 | C19: 0 | D19: 0 | E19: 0 | F19: =B19+C19+E19-D19 | G19: =D19*$B$6 | H19: =D19*$B$8
B20: =F19 | C20: 0 | D20: 0 | E20: 0 | F20: =B20+C20+E20-D20 | G20: =D20*$B$6 | H20: =D20*$B$8
B21: =F20 | C21: 0 | D21: 0 | E21: 0 | F21: =B21+C21+E21-D21 | G21: =D21*$B$6 | H21: =D21*$B$8
B22: =F21 | C22: 0 | D22: 0 | E22: 0 | F22: =B22+C22+E22-D22 | G22: =D22*$B$6 | H22: =D22*$B$8
B23: =F22 | C23: 0 | D23: 0 | E23: 0 | F23: =B23+C23+E23-D23 | G23: =D23*$B$6 | H23: =D23*$B$8
... B110: =F109 | C110: 0 | D110: 0 | E110: 0 | F110: =B110+C110+E110-D110 | G110: =D110*$B$6 | H110: =D110*$B$8

Sheet 14 Mens Woven Sweaters Style 81
A1: Stock Item Tracking Sheet
A2: Item No. | B2: 14
A3: Product name | B3: Men's Woven Sweaters (Style 8102)
A4: Initial stock quantity | B4: 12
A5: Unit cost (RMB) | B5: 30
A6: Selling price/item (RMB) | B6: 60
A7: Unit cost (USD) | B7: 4.43
A8: Selling price/item (USD) | B8: 8.87
A10: Date | B10: Opening balance | C10: Stock received | D10: Quantity sold | E10: Returns | F10: Closing balance | G10: Sales value (RMB) | H10: Sales value (USD) | I10: Notes
B11: =$B$4 | C11: 0 | D11: 0 | E11: 0 | F11: =B11+C11+E11-D11 | G11: =D11*$B$6 | H11: =D11*$B$8
B12: =F11 | C12: 0 | D12: 0 | E12: 0 | F12: =B12+C12+E12-D12 | G12: =D12*$B$6 | H12: =D12*$B$8
B13: =F12 | C13: 0 | D13: 0 | E13: 0 | F13: =B13+C13+E13-D13 | G13: =D13*$B$6 | H13: =D13*$B$8
B14: =F13 | C14: 0 | D14: 0 | E14: 0 | F14: =B14+C14+E14-D14 | G14: =D14*$B$6 | H14: =D14*$B$8
B15: =F14 | C15: 0 | D15: 0 | E15: 0 | F15: =B15+C15+E15-D15 | G15: =D15*$B$6 | H15: =D15*$B$8
B16: =F15 | C16: 0 | D16: 0 | E16: 0 | F16: =B16+C16+E16-D16 | G16: =D16*$B$6 | H16: =D16*$B$8
B17: =F16 | C17: 0 | D17: 0 | E17: 0 | F17: =B17+C17+E17-D17 | G17: =D17*$B$6 | H17: =D17*$B$8
B18: =F17 | C18: 0 | D18: 0 | E18: 0 | F18: =B18+C18+E18-D18 | G18: =D18*$B$6 | H18: =D18*$B$8
B19: =F18 | C19: 0 | D19: 0 | E19: 0 | F19: =B19+C19+E19-D19 | G19: =D19*$B$6 | H19: =D19*$B$8
B20: =F19 | C20: 0 | D20: 0 | E20: 0 | F20: =B20+C20+E20-D20 | G20: =D20*$B$6 | H20: =D20*$B$8
B21: =F20 | C21: 0 | D21: 0 | E21: 0 | F21: =B21+C21+E21-D21 | G21: =D21*$B$6 | H21: =D21*$B$8
B22: =F21 | C22: 0 | D22: 0 | E22: 0 | F22: =B22+C22+E22-D22 | G22: =D22*$B$6 | H22: =D22*$B$8
B23: =F22 | C23: 0 | D23: 0 | E23: 0 | F23: =B23+C23+E23-D23 | G23: =D23*$B$6 | H23: =D23*$B$8
... B110: =F109 | C110: 0 | D110: 0 | E110: 0 | F110: =B110+C110+E110-D110 | G110: =D110*$B$6 | H110: =D110*$B$8

Sheet 15 Commercial Stationery Writin
A1: Stock Item Tracking Sheet
A2: Item No. | B2: 15
A3: Product name | B3: Commercial Stationery Writing Pens
A4: Initial stock quantity | B4: 88
A5: Unit cost (RMB) | B5: 3.5
A6: Selling price/item (RMB) | B6: 7
A7: Unit cost (USD) | B7: 0.52
A8: Selling price/item (USD) | B8: 1.03
A10: Date | B10: Opening balance | C10: Stock received | D10: Quantity sold | E10: Returns | F10: Closing balance | G10: Sales value (RMB) | H10: Sales value (USD) | I10: Notes
B11: =$B$4 | C11: 0 | D11: 0 | E11: 0 | F11: =B11+C11+E11-D11 | G11: =D11*$B$6 | H11: =D11*$B$8
B12: =F11 | C12: 0 | D12: 0 | E12: 0 | F12: =B12+C12+E12-D12 | G12: =D12*$B$6 | H12: =D12*$B$8
B13: =F12 | C13: 0 | D13: 0 | E13: 0 | F13: =B13+C13+E13-D13 | G13: =D13*$B$6 | H13: =D13*$B$8
B14: =F13 | C14: 0 | D14: 0 | E14: 0 | F14: =B14+C14+E14-D14 | G14: =D14*$B$6 | H14: =D14*$B$8
B15: =F14 | C15: 0 | D15: 0 | E15: 0 | F15: =B15+C15+E15-D15 | G15: =D15*$B$6 | H15: =D15*$B$8
B16: =F15 | C16: 0 | D16: 0 | E16: 0 | F16: =B16+C16+E16-D16 | G16: =D16*$B$6 | H16: =D16*$B$8
B17: =F16 | C17: 0 | D17: 0 | E17: 0 | F17: =B17+C17+E17-D17 | G17: =D17*$B$6 | H17: =D17*$B$8
B18: =F17 | C18: 0 | D18: 0 | E18: 0 | F18: =B18+C18+E18-D18 | G18: =D18*$B$6 | H18: =D18*$B$8
B19: =F18 | C19: 0 | D19: 0 | E19: 0 | F19: =B19+C19+E19-D19 | G19: =D19*$B$6 | H19: =D19*$B$8
B20: =F19 | C20: 0 | D20: 0 | E20: 0 | F20: =B20+C20+E20-D20 | G20: =D20*$B$6 | H20: =D20*$B$8
B21: =F20 | C21: 0 | D21: 0 | E21: 0 | F21: =B21+C21+E21-D21 | G21: =D21*$B$6 | H21: =D21*$B$8
B22: =F21 | C22: 0 | D22: 0 | E22: 0 | F22: =B22+C22+E22-D22 | G22: =D22*$B$6 | H22: =D22*$B$8
B23: =F22 | C23: 0 | D23: 0 | E23: 0 | F23: =B23+C23+E23-D23 | G23: =D23*$B$6 | H23: =D23*$B$8
... B110: =F109 | C110: 0 | D110: 0 | E110: 0 | F110: =B110+C110+E110-D110 | G110: =D110*$B$6 | H110: =D110*$B$8

Sheet 16 Ladies Fashion Dresses
A1: Stock Item Tracking Sheet
A2: Item No. | B2: 16
A3: Product name | B3: Ladies' Fashion Dresses
A4: Initial stock quantity | B4: 83
A5: Unit cost (RMB) | B5: 11.51
A6: Selling price/item (RMB) | B6: 23.02
A7: Unit cost (USD) | B7: 1.7
A8: Selling price/item (USD) | B8: 3.4
A10: Date | B10: Opening balance | C10: Stock received | D10: Quantity sold | E10: Returns | F10: Closing balance | G10: Sales value (RMB) | H10: Sales value (USD) | I10: Notes
B11: =$B$4 | C11: 0 | D11: 0 | E11: 0 | F11: =B11+C11+E11-D11 | G11: =D11*$B$6 | H11: =D11*$B$8
B12: =F11 | C12: 0 | D12: 0 | E12: 0 | F12: =B12+C12+E12-D12 | G12: =D12*$B$6 | H12: =D12*$B$8
B13: =F12 | C13: 0 | D13: 0 | E13: 0 | F13: =B13+C13+E13-D13 | G13: =D13*$B$6 | H13: =D13*$B$8
B14: =F13 | C14: 0 | D14: 0 | E14: 0 | F14: =B14+C14+E14-D14 | G14: =D14*$B$6 | H14: =D14*$B$8
B15: =F14 | C15: 0 | D15: 0 | E15: 0 | F15: =B15+C15+E15-D15 | G15: =D15*$B$6 | H15: =D15*$B$8
B16: =F15 | C16: 0 | D16: 0 | E16: 0 | F16: =B16+C16+E16-D16 | G16: =D16*$B$6 | H16: =D16*$B$8
B17: =F16 | C17: 0 | D17: 0 | E17: 0 | F17: =B17+C17+E17-D17 | G17: =D17*$B$6 | H17: =D17*$B$8
B18: =F17 | C18: 0 | D18: 0 | E18: 0 | F18: =B18+C18+E18-D18 | G18: =D18*$B$6 | H18: =D18*$B$8
B19: =F18 | C19: 0 | D19: 0 | E19: 0 | F19: =B19+C19+E19-D19 | G19: =D19*$B$6 | H19: =D19*$B$8
B20: =F19 | C20: 0 | D20: 0 | E20: 0 | F20: =B20+C20+E20-D20 | G20: =D20*$B$6 | H20: =D20*$B$8
B21: =F20 | C21: 0 | D21: 0 | E21: 0 | F21: =B21+C21+E21-D21 | G21: =D21*$B$6 | H21: =D21*$B$8
B22: =F21 | C22: 0 | D22: 0 | E22: 0 | F22: =B22+C22+E22-D22 | G22: =D22*$B$6 | H22: =D22*$B$8
B23: =F22 | C23: 0 | D23: 0 | E23: 0 | F23: =B23+C23+E23-D23 | G23: =D23*$B$6 | H23: =D23*$B$8
... B110: =F109 | C110: 0 | D110: 0 | E110: 0 | F110: =B110+C110+E110-D110 | G110: =D110*$B$6 | H110: =D110*$B$8

Sheet 17 Ladies Long Dresses
A1: Stock Item Tracking Sheet
A2: Item No. | B2: 17
A3: Product name | B3: Ladies' Long Dresses
A4: Initial stock quantity | B4: 24
A5: Unit cost (RMB) | B5: 25
A6: Selling price/item (RMB) | B6: 50
A7: Unit cost (USD) | B7: 3.69
A8: Selling price/item (USD) | B8: 7.39
A10: Date | B10: Opening balance | C10: Stock received | D10: Quantity sold | E10: Returns | F10: Closing balance | G10: Sales value (RMB) | H10: Sales value (USD) | I10: Notes
B11: =$B$4 | C11: 0 | D11: 0 | E11: 0 | F11: =B11+C11+E11-D11 | G11: =D11*$B$6 | H11: =D11*$B$8
B12: =F11 | C12: 0 | D12: 0 | E12: 0 | F12: =B12+C12+E12-D12 | G12: =D12*$B$6 | H12: =D12*$B$8
B13: =F12 | C13: 0 | D13: 0 | E13: 0 | F13: =B13+C13+E13-D13 | G13: =D13*$B$6 | H13: =D13*$B$8
B14: =F13 | C14: 0 | D14: 0 | E14: 0 | F14: =B14+C14+E14-D14 | G14: =D14*$B$6 | H14: =D14*$B$8
B15: =F14 | C15: 0 | D15: 0 | E15: 0 | F15: =B15+C15+E15-D15 | G15: =D15*$B$6 | H15: =D15*$B$8
B16: =F15 | C16: 0 | D16: 0 | E16: 0 | F16: =B16+C16+E16-D16 | G16: =D16*$B$6 | H16: =D16*$B$8
B17: =F16 | C17: 0 | D17: 0 | E17: 0 | F17: =B17+C17+E17-D17 | G17: =D17*$B$6 | H17: =D17*$B$8
B18: =F17 | C18: 0 | D18: 0 | E18: 0 | F18: =B18+C18+E18-D18 | G18: =D18*$B$6 | H18: =D18*$B$8
B19: =F18 | C19: 0 | D19: 0 | E19: 0 | F19: =B19+C19+E19-D19 | G19: =D19*$B$6 | H19: =D19*$B$8
B20: =F19 | C20: 0 | D20: 0 | E20: 0 | F20: =B20+C20+E20-D20 | G20: =D20*$B$6 | H20: =D20*$B$8
B21: =F20 | C21: 0 | D21: 0 | E21: 0 | F21: =B21+C21+E21-D21 | G21: =D21*$B$6 | H21: =D21*$B$8
B22: =F21 | C22: 0 | D22: 0 | E22: 0 | F22: =B22+C22+E22-D22 | G22: =D22*$B$6 | H22: =D22*$B$8
B23: =F22 | C23: 0 | D23: 0 | E23: 0 | F23: =B23+C23+E23-D23 | G23: =D23*$B$6 | H23: =D23*$B$8
... B110: =F109 | C110: 0 | D110: 0 | E110: 0 | F110: =B110+C110+E110-D110 | G110: =D110*$B$6 | H110: =D110*$B$8

Sheet 18 Ladies Black Dresses
A1: Stock Item Tracking Sheet
A2: Item No. | B2: 18
A3: Product name | B3: Ladies' Black Dresses
A4: Initial stock quantity | B4: 10
A5: Unit cost (RMB) | B5: 45
A6: Selling price/item (RMB) | B6: 90
A7: Unit cost (USD) | B7: 6.65
A8: Selling price/item (USD) | B8: 13.3
A10: Date | B10: Opening balance | C10: Stock received | D10: Quantity sold | E10: Returns | F10: Closing balance | G10: Sales value (RMB) | H10: Sales value (USD) | I10: Notes
B11: =$B$4 | C11: 0 | D11: 0 | E11: 0 | F11: =B11+C11+E11-D11 | G11: =D11*$B$6 | H11: =D11*$B$8
B12: =F11 | C12: 0 | D12: 0 | E12: 0 | F12: =B12+C12+E12-D12 | G12: =D12*$B$6 | H12: =D12*$B$8
B13: =F12 | C13: 0 | D13: 0 | E13: 0 | F13: =B13+C13+E13-D13 | G13: =D13*$B$6 | H13: =D13*$B$8
B14: =F13 | C14: 0 | D14: 0 | E14: 0 | F14: =B14+C14+E14-D14 | G14: =D14*$B$6 | H14: =D14*$B$8
B15: =F14 | C15: 0 | D15: 0 | E15: 0 | F15: =B15+C15+E15-D15 | G15: =D15*$B$6 | H15: =D15*$B$8
B16: =F15 | C16: 0 | D16: 0 | E16: 0 | F16: =B16+C16+E16-D16 | G16: =D16*$B$6 | H16: =D16*$B$8
B17: =F16 | C17: 0 | D17: 0 | E17: 0 | F17: =B17+C17+E17-D17 | G17: =D17*$B$6 | H17: =D17*$B$8
B18: =F17 | C18: 0 | D18: 0 | E18: 0 | F18: =B18+C18+E18-D18 | G18: =D18*$B$6 | H18: =D18*$B$8
B19: =F18 | C19: 0 | D19: 0 | E19: 0 | F19: =B19+C19+E19-D19 | G19: =D19*$B$6 | H19: =D19*$B$8
B20: =F19 | C20: 0 | D20: 0 | E20: 0 | F20: =B20+C20+E20-D20 | G20: =D20*$B$6 | H20: =D20*$B$8
B21: =F20 | C21: 0 | D21: 0 | E21: 0 | F21: =B21+C21+E21-D21 | G21: =D21*$B$6 | H21: =D21*$B$8
B22: =F21 | C22: 0 | D22: 0 | E22: 0 | F22: =B22+C22+E22-D22 | G22: =D22*$B$6 | H22: =D22*$B$8
B23: =F22 | C23: 0 | D23: 0 | E23: 0 | F23: =B23+C23+E23-D23 | G23: =D23*$B$6 | H23: =D23*$B$8
... B110: =F109 | C110: 0 | D110: 0 | E110: 0 | F110: =B110+C110+E110-D110 | G110: =D110*$B$6 | H110: =D110*$B$8

Sheet 19 Ladies 2Piece Suits Brown
A1: Stock Item Tracking Sheet
A2: Item No. | B2: 19
A3: Product name | B3: Ladies' 2-Piece Suits (Brown)
A4: Initial stock quantity | B4: 1
A5: Unit cost (RMB) | B5: 40
A6: Selling price/item (RMB) | B6: 80
A7: Unit cost (USD) | B7: 5.91
A8: Selling price/item (USD) | B8: 11.82
A10: Date | B10: Opening balance | C10: Stock received | D10: Quantity sold | E10: Returns | F10: Closing balance | G10: Sales value (RMB) | H10: Sales value (USD) | I10: Notes
B11: =$B$4 | C11: 0 | D11: 0 | E11: 0 | F11: =B11+C11+E11-D11 | G11: =D11*$B$6 | H11: =D11*$B$8
B12: =F11 | C12: 0 | D12: 0 | E12: 0 | F12: =B12+C12+E12-D12 | G12: =D12*$B$6 | H12: =D12*$B$8
B13: =F12 | C13: 0 | D13: 0 | E13: 0 | F13: =B13+C13+E13-D13 | G13: =D13*$B$6 | H13: =D13*$B$8
B14: =F13 | C14: 0 | D14: 0 | E14: 0 | F14: =B14+C14+E14-D14 | G14: =D14*$B$6 | H14: =D14*$B$8
B15: =F14 | C15: 0 | D15: 0 | E15: 0 | F15: =B15+C15+E15-D15 | G15: =D15*$B$6 | H15: =D15*$B$8
B16: =F15 | C16: 0 | D16: 0 | E16: 0 | F16: =B16+C16+E16-D16 | G16: =D16*$B$6 | H16: =D16*$B$8
B17: =F16 | C17: 0 | D17: 0 | E17: 0 | F17: =B17+C17+E17-D17 | G17: =D17*$B$6 | H17: =D17*$B$8
B18: =F17 | C18: 0 | D18: 0 | E18: 0 | F18: =B18+C18+E18-D18 | G18: =D18*$B$6 | H18: =D18*$B$8
